Workbook

Sheet Bebidas
A1: COMPRAS BEBIDAS 2026-2
A2: POSTOBON
A3: PRODUCTO | B3: CAJA POR | C3: COSTO CAJA | D3: COSTO CON IVA | E3: COSTO UNITARIO | F3: PEDIDO 2025 | G3: PEDIDO UNDS 2026-2 | H3: PEDIDO CAJAS | I3: DEVOLUCIONES X CAJAS | J3: DEVOLUCIONES EN DINERO | K3: VENTA FINAL X CAJA | L3: VENTA FINAL X UND | M3: VALOR COMPRA | N3: PRECIO DE VENTA | O3: VENTA X ITEM | P3: UTILIDAD | Q3: % UTILIDAD | R3: UTILIDAD PROYECTADA
A4: Jugo Hit 500ml (Naranja piña ) | B4: 12 | C4: 25000 | D4: =C4*1.19 -> 29750 | E4: =D4/B4 -> 2479.1667 | F4: 360 | G4: =H4*B4 -> 600 | H4: 50 | I4: 19 | J4: =I4*C4 -> 475000 | K4: =H4-I4 -> 31 | L4: =K4*B4 -> 372 | M4: =L4*E4 -> 922250 | N4: 5000 | O4: =N4*L4 -> 1860000 | P4: =N4-E4 -> 2520.8333 | Q4: =(N4-E4)/E4 -> 1.0168067 | R4: =L4*P4 -> 937750
A5: Squash (frutas tropicales ) | B5: 12 | C5: 22500 | D5: =C5*1.19 -> 26775 | E5: =D5/B5 -> 2231.25 | F5: 360 | G5: =H5*B5 -> 600 | H5: 50 | J5: =I5*C5 -> 0 | L5: =K5*B5 -> 0 | M5: =L5*E5 -> 0 | N5: 5000 | O5: =N5*L5 -> 0 | P5: =N5-E5 -> 2768.75 | Q5: =(N5-E5)/E5 -> 1.2408964 | R5: =L5*P5 -> 0
A6: Gaseosa manzana postobon 400ml | B6: 15 | C6: 31250 | D6: =C6*1.19 -> 37187.5 | E6: =D6/B6 -> 2479.1667 | F6: 360 | G6: =H6*B6 -> 225 | H6: 15 | I6: 5 | J6: =I6*C6 -> 156250 | K6: =H6-I6 -> 10 | L6: =K6*B6 -> 150 | M6: =L6*E6 -> 371875 | N6: 5000 | O6: =N6*L6 -> 750000 | P6: =N6-E6 -> 2520.8333 | Q6: =(N6-E6)/E6 -> 1.0168067 | R6: =L6*P6 -> 378125
A7: Colombiana nacional 400 ml | B7: 15 | C7: 31250 | D7: =C7*1.19 -> 37187.5 | E7: =D7/B7 -> 2479.1667 | F7: 360 | G7: =H7*B7 -> 225 | H7: 15 | I7: 7 | J7: =I7*C7 -> 218750 | K7: =H7-I7 -> 8 | L7: =K7*B7 -> 120 | M7: =L7*E7 -> 297500 | N7: 5000 | O7: =N7*L7 -> 600000 | P7: =N7-E7 -> 2520.8333 | Q7: =(N7-E7)/E7 -> 1.0168067 | R7: =L7*P7 -> 302500
A8: Uva postobon 400 ml | B8: 15 | C8: 31250 | D8: =C8*1.19 -> 37187.5 | E8: =D8/B8 -> 2479.1667 | F8: 360 | G8: =H8*B8 -> 150 | H8: 10 | I8: 2 | J8: =I8*C8 -> 62500 | K8: =H8-I8 -> 8 | L8: =K8*B8 -> 120 | M8: =L8*E8 -> 297500 | N8: 5000 | O8: =N8*L8 -> 600000 | P8: =N8-E8 -> 2520.8333 | Q8: =(N8-E8)/E8 -> 1.0168067 | R8: =L8*P8 -> 302500
A9: Naranja postobon 400 ml | B9: 15 | C9: 31250 | D9: =C9*1.19 -> 37187.5 | E9: =D9/B9 -> 2479.1667 | F9: 360 | G9: =H9*B9 -> 150 | H9: 10 | I9: 5 | J9: =I9*C9 -> 156250 | K9: =H9-I9 -> 5 | L9: =K9*B9 -> 75 | M9: =L9*E9 -> 185937.5 | N9: 5000 | O9: =N9*L9 -> 375000 | P9: =N9-E9 -> 2520.8333 | Q9: =(N9-E9)/E9 -> 1.0168067 | R9: =L9*P9 -> 189062.5
A10: Speedmax 250ml | B10: 24 | C10: 39999 | D10: =C10*1.19 -> 47598.81 | E10: =D10/B10 -> 1983.2837 | G10: =H10*B10 -> 720 | H10: 30 | I10: 16 | J10: =I10*C10 -> 639984 | K10: =H10-I10 -> 14 | L10: =K10*B10 -> 336 | M10: =L10*E10 -> 666383.34 | N10: 5000 | O10: =N10*L10 -> 1680000 | P10: =N10-E10 -> 3016.7163 | Q10: =(N10-E10)/E10 -> 1.5210714 | R10: =L10*P10 -> 1013616.7
A11: Cerveza Andina Lata 269ml | B11: 24 | C11: 40000 | D11: =C11*1.19 -> 47600 | E11: =D11/B11 -> 1983.3333 | F11: 2256 | G11: =H11*B11 -> 6000 | H11: 250 | I11: 111 | J11: =I11*C11 -> 4440000 | K11: =H11-I11 -> 139 | L11: =K11*B11 -> 3336 | M11: =L11*E11 -> 6616400 | N11: 5000 | O11: =N11*L11 -> 16680000 | P11: =N11-E11 -> 3016.6667 | Q11: =(N11-E11)/E11 -> 1.5210084 | R11: =L11*P11 -> 10063600
A12: Cerveza Heineken lata 269ml | B12: 24 | C12: 57600 | D12: =C12*1.19 -> 68544 | E12: =D12/B12 -> 2856 | F12: 2808 | G12: =H12*B12 -> 4800 | H12: 200 | I12: 0 | J12: =I12*C12 -> 0 | K12: =H12-I12 -> 200 | L12: =K12*B12 -> 4800 | M12: =L12*E12 -> 13708800 | N12: 5000 | O12: =N12*L12 -> 24000000 | P12: =N12-E12 -> 2144 | Q12: =(N12-E12)/E12 -> 0.75070028 | R12: =L12*P12 -> 10291200
G13: =SUM(G4:G12) -> 13470 | H13: =SUM(H4:H12) -> 630 | J13: =SUM(J4:J12) -> 6148734 | K13: =SUM(K4:K12) -> 415 | L13: =SUM(L4:L12) -> 9309 | M13: =SUM(M4:M12) -> 23066646 | O13: =SUM(O4:O12) -> 46545000 | R13: =SUM(R4:R12) -> 23478354
A17: COCA COLA
A18: PRODUCTO | B18: CAJA POR | C18: PRECIO CAJA | D18: COSTO CON IVA | E18: PRECIO UNITARIO | F18: PEDIDO 2025 | G18: PEDIDO UNDS 2026-2 | H18: PEDIDO EN CAJAS | I18: DEVOLUCIONES X CAJA | J18: DEVOLUCIONES EN DINERO | K18: VENTA FINAL X CAJA | L18: VENTA FINAL X UND | M18: VALOR TOTAL | N18: PRECIO DE VENTA | O18: VENTA X ITEM | P18: UTILIDAD | Q18: % UTILIDAD | R18: UTILIDAD PROYECTADA
A19: Coca Cola Original 400 ml | B19: 12 | C19: 22467 | D19: =C19*1.19 -> 26735.73 | E19: =D19/B19 -> 2227.9775 | F19: 108 | G19: =H19*B19 -> 600 | H19: 50 | I19: 0 | J19: =I19*C19 -> 0 | K19: =H19-I19 -> 50 | L19: =K19*B19 -> 600 | M19: =E19*L19 -> 1336786.5 | N19: 5000 | O19: =N19*L19 -> 3000000 | P19: =N19-E19 -> 2772.0225 | Q19: =P19/E19 -> 1.2441878 | R19: =P19*G19 -> 1663213.5
A20: Powerade Azul | B20: 6 | C20: 15966 | D20: =C20*1.19 -> 18999.54 | E20: =D20/B20 -> 3166.59 | F20: 72 | G20: =H20*B20 -> 120 | H20: 20 | I20: 0 | J20: =I20*C20 -> 0 | K20: =H20-I20 -> 20 | L20: =K20*B20 -> 120 | M20: =E20*L20 -> 379990.8 | N20: 5000 | O20: =N20*L20 -> 600000 | P20: =N20-E20 -> 1833.41 | Q20: =P20/E20 -> 0.5789856 | R20: =P20*G20 -> 220009.2
A21: Powerade Rojo | B21: 6 | C21: 15966 | D21: =C21*1.19 -> 18999.54 | E21: =D21/B21 -> 3166.59 | G21: =H21*B21 -> 120 | H21: 20 | I21: 0 | J21: =I21*C21 -> 0 | K21: =H21-I21 -> 20 | L21: =K21*B21 -> 120 | M21: =E21*L21 -> 379990.8 | N21: 5000 | O21: =N21*L21 -> 600000 | P21: =N21-E21 -> 1833.41 | Q21: =P21/E21 -> 0.5789856 | R21: =P21*G21 -> 220009.2
A22: Coca Cola Zero 400 ml | B22: 12 | C22: 24202 | D22: =C22*1.19 -> 28800.38 | E22: =D22/B22 -> 2400.0317 | F22: 72 | G22: =H22*B22 -> 360 | H22: 30 | I22: 7 | J22: =I22*C22 -> 169414 | K22: =H22-I22 -> 23 | L22: =K22*B22 -> 276 | M22: =E22*L22 -> 662408.74 | N22: 5000 | O22: =N22*L22 -> 1380000 | P22: =N22-E22 -> 2599.9683 | Q22: =P22/E22 -> 1.0833058 | R22: =P22*G22 -> 935988.6
A23: Kola Roman 400ml | B23: 12 | C23: 19479 | D23: =C23*1.19 -> 23180.01 | E23: =D23/B23 -> 1931.6675 | G23: =H23*B23 -> 360 | H23: 30 | I23: 18 | J23: =I23*C23 -> 350622 | K23: =H23-I23 -> 12 | L23: =K23*B23 -> 144 | M23: =E23*L23 -> 278160.12 | N23: 5000 | O23: =N23*L23 -> 720000 | P23: =N23-E23 -> 3068.3325 | Q23: =P23/E23 -> 1.5884372 | R23: =P23*G23 -> 1104599.7
A24: Agua Saborizada Manzana 600ml | B24: 6 | C24: 10504 | D24: =C24*1.19 -> 12499.76 | E24: =D24/B24 -> 2083.2933 | G24: =H24*B24 -> 864 | H24: 144 | I24: 116 | J24: =I24*C24 -> 1218464 | K24: =H24-I24 -> 28 | L24: =K24*B24 -> 168 | M24: =E24*L24 -> 349993.28 | N24: 5000 | O24: =N24*L24 -> 840000 | P24: =N24-E24 -> 2916.7067 | Q24: =P24/E24 -> 1.4000461 | R24: =P24*G24 -> 2520034.6
G25: =SUM(G19:G24) -> 2424 | H25: =SUM(H19:H24) -> 294 | J25: =SUM(J19:J24) -> 1738500 | M25: =SUM(M19:M24) -> 3387330.2 | O25: =SUM(O19:O24) -> 7140000 | R25: =SUM(R19:R24) -> 6663854.8
A27: EL REY DE LAS AGUAS
A28: PRODUCTO | B28: CAJA POR | C28: PRECIO CAJA | D28: COSTO CON IVA | E28: PRECIO UNITARIO | F28: PEDIDO 2025 | G28: PEDIDO 2026 | H28: PEDIDO EN CAJAS | I28: DEVOLUCIONES X CAJA | J28: DEVOLUCIONES EN DINERO | K28: VENTA FINAL X CAJA | L28: VENTA FINAL X UND | M28: VALOR TOTAL | N28: PRECIO DE VENTA | O28: VENTA X ITEM | P28: UTILIDAD | Q28: % UTILIDAD | R28: UTILIDAD PROYECTADA
A29: Agua 500ml Reserva | B29: 24 | C29: 13000 | E29: =C29/B29 -> 541.66667 | F29: 108 | G29: =H29*B29 -> 2400 | H29: 100 | I29: 57 | K29: =H29-I29 -> 43 | L29: =K29*B29 -> 1032 | M29: =K29*C29 -> 559000 | N29: 5000 | O29: =L29*N29 -> 5160000 | P29: =N29-E29 -> 4458.3333 | Q29: =P29/E29 -> 8.2307692 | R29: =L29*P29 -> 4601000
A30: Pacas de agua en bolsa | B30: 24 | C30: 4000 | E30: =C30/B30 -> 166.66667 | G30: =H30*B30 -> 480 | H30: 20 | I30: 0 | K30: =H30-I30 -> 20 | L30: =K30*B30 -> 480 | M30: =G30*E30 -> 80000 | N30: 10000 | O30: =L30*N30 -> 4800000 | P30: =N30-E30 -> 9833.3333 | Q30: =P30/E30 -> 59 | R30: 0
A31: Hidralyte | B31: 24 | C31: =E31*B31 -> 96000 | E31: 4000 | G31: =H31*B31 -> 480 | H31: 20 | I31: 13 | K31: =H31-I31 -> 7 | L31: =K31*B31 -> 168 | M31: =G31*E31 -> 1920000 | N31: 10000 | O31: =L31*N31 -> 1680000 | P31: =N31-E31 -> 6000 | Q31: =P31/E31 -> 1.5 | R31: =L31*P31 -> 1008000
M32: =SUM(M29:M31) -> 2559000 | O32: =SUM(O29:O31) -> 11640000 | R32: =SUM(R29:R31) -> 5609000
L34: COSTO TOTAL | M34: =M13+M25+M32 -> 29012976 | N34: VENTA TOTAL | O34: =O13+O25+O32 -> 65325000
A35: RELACION GASTOS | B35: VALOR | C35: ANTICIPO ANTES DEL EVENTO | E35: DEBE A FRANCISCO
A36: Hielo + Transporte | B36: =75000*15+160000 -> 1285000 | C36: =B36 -> 1285000 | H36: Inversión | M36: =M13+M25+M32 -> 29012976 | N36: Anticipo 50% x socio | Q36: Utilidad | R36: =R13+R25+R32 -> 35751209
A37: Chalecos | B37: =65000*9 -> 585000 | H37: Inversión x socio | M37: =M36/2 -> 14506488 | N37: =M37/2 -> 7253244 | Q37: Utilidad x socio | R37: =R36/2-P37 -> 17875604
A38: Cajas registradoras | B38: 420000 | E38: =B38 -> 420000
A39: Pago personal | B39: =200000*8 -> 1600000
A40: Almuerzos | B40: =25000*9 -> 225000 | C40: =B40 -> 225000 | N40: =M36+R36 -> 64764185
A41: Datafonos | B41: 174000 | E41: =B41 -> 174000
A42: Menudo para entrega de cajas | B42: 5000000 | C42: 5000000
A43: Productos postobon | B43: =M13 -> 23066646 | C43: =B43*50% -> 11533323
A44: Cocacola | B44: =M25 -> 3387330.2 | C44: =B44 -> 3387330.2
A45: Agua iglu | B45: =#REF! -> #REF! | C45: =B45 -> #REF!
...

Sheet Comparativo compras bebidas
A1: COMPARATIVO BEBIDAS 2026-1 VS 2026-2
A2: 2026-1 | B2: Unidades | D2: 2026-2 | E2: Unidades
A3: Jugos Hit | B3: 60 | D3: SQUASH Frutas Tropical 500ml | E3: 600
A4: SQUASH Frutas Tropical 500ml | B4: 360 | D4: Jugo Hit 500ml | E4: 360
A5: Gaseosa 400ml | B5: 270 | D5: Gaseosa 400ml | E5: 750
A6: Red Bull Lata 250ml | B6: 120 | D6: Speedmax 250ml | E6: 360
A7: Cerveza Andina Lata 269ml | B7: 720 | D7: Cerveza Andina Lata 269ml | E7: 0
A8: Cerveza Andina Light Lata 269ml | B8: 720 | D8: Cerveza Heineken lata 269ml | E8: 4800
A9: Cerveza Heineken lata 310ml | B9: 4800 | E9: =SUM(E3:E8) -> 6870
B10: =SUM(B3:B9) -> 7050
A11: Coca Cola Original 400 ml | B11: 336 | D11: Coca Cola Original 400 ml | E11: 600
A12: Coca Cola Zero 400 ml | B12: 96 | D12: Coca Cola Zero 400 ml | E12: 360
A13: Kola Roman 400ml | B13: 144 | D13: Kola Roman 400ml | E13: 360
A14: Agua Saborizada Manzana 600ml | B14: 90 | D14: Agua Saborizada Manzana 600ml | E14: 240
A15: Agua Brisa 600ml | B15: 960 | E15: =SUM(E11:E14) -> 1560
B16: =SUM(B11:B15) -> 1626
D17: Agua 500ml Reserva | E17: 1200
D18: Agua 500ml Reserva con GAS | E18: 1200
D19: Hidralyte | E19: 360
E20: =SUM(E17:E19) -> 2760

Sheet Mobiliario
A1: MOBILIARIO
A2: DECORFIESTAS
A3: PRODUCTO | B3: CANTIDAD | C3: COSTO UNITARIO | D3: PEDIDO 2025 | E3: VALOR VENTA | F3: UTILIDAD | G3: TOTALCOMPRA | H3: TOTAL VENTA | I3: UTILIDAD PROYECTADA
A4: Sillas rimax | B4: 1000 | C4: 1200 | D4: 300 | E4: 1450 | F4: =E4-C4 -> 250 | G4: =B4*C4 -> 1200000 | H4: =B4*E4 -> 1450000 | I4: =H4-G4 -> 250000
A5: Tablones Grandes | B5: 140 | C5: 9000 | D5: 360 | E5: 11500 | F5: =E5-C5 -> 2500 | G5: =B5*C5 -> 1260000 | H5: =B5*E5 -> 1610000 | I5: =H5-G5 -> 350000
A6: Manteles rectangulares blancos | B6: 200 | C6: 9000 | D6: 360 | E6: 11500 | F6: =E6-C6 -> 2500 | G6: =B6*C6 -> 1800000 | H6: =B6*E6 -> 2300000 | I6: =H6-G6 -> 500000
A7: Transporte | B7: 1 | C7: 1100000 | E7: 1100000 | F7: =E7-C7 -> 0 | G7: =B7*C7 -> 1100000 | H7: =B7*E7 -> 1100000 | I7: =H7-G7 -> 0
E8: =SUM(E4:E7) -> 1124450 | F8: =SUM(F4:F7) -> 5250 | G8: =SUM(G4:G7) -> 5360000 | H8: =SUM(H4:H7) -> 6460000 | I8: =SUM(I4:I7) -> 1100000
A10: ANTICIPO ANTES DEL EVENTO | B10: 3500000

Sheet Cuentas Produccion
A1: COTIZACION CLIENTE | B1: 63000000
A2: SALDO PENDIENTE | B2: =B1-B3-B4 -> 21000000
A3: 46284 | B3: 22000000
A4: 46290 | B4: 20000000
A5: COSTOS | C5: ANTICIPO 1 | D5: ANTICIPO 2 | F5: ANTICIPOS ANTES DEL EVENTO | G5: PENDIENTE POR PAGAR | H5: PAGOS A FRANCISCO | I5: PAGOS A LORCY
A6: RV | B6: 35000000 | C6: 14000000 | D6: 3500000 | G6: =B6-C6-D6 -> 17500000
A7: Omar | B7: 2100000 | G7: =B7 -> 2100000
A8: Aba Carpas | B8: 7700000 | C8: 4000000 | G8: =B8-C8 -> 3700000
A9: Inflables | B9: 2048000 | D9: 1000000 | F9: =B9-D9 -> 1048000
A10: TV+PS5 | B10: 1400000 | C10: 700000 | D10: 700000 | F10: =B10-D10 -> 700000
A11: Ricardo | B11: 1100000 | G11: =B11 -> 1100000
A12: Chalecos | B12: 975000 | C12: 450000 | F12: =B12-C12 -> 525000 | G12: =B12-C12 -> 525000 | H12: =C12 -> 450000
A13: Reflectores | B13: 263060 | C13: 263060 | H13: =B13 -> 263060
A14: Alimentación | B14: =45000*8 -> 360000 | F14: 360000
A15: Radio de comunicación | B15: 160000 | C15: 160000 | H15: =B15 -> 160000
A16: Luz de feria | B16: 484782 | C16: 484782 | H16: =B16 -> 484782
A17: Imprevistos | B17: 1000000 | F17: =B17 -> 1000000
A18: Clavijas de refelctores | B18: 63000 | C18: 63000 | H18: =B18 -> 63000
A19: 40 mts cable y clavilas | B19: 200000 | C19: 200000 | H19: =B19 -> 200000
A20: Camiseta polo Blanca y camisa azul | B20: 174000 | I20: =B20 -> 174000
B21: =SUM(B6:B20) -> 53027842
A22: Utilidad | B22: =[1]Cotización!E69-B21 -> 9972158 | C22: =SUM(C6:C21) -> 20320842 | D22: =SUM(D7:D21) -> 1700000 | F22: =SUM(F6:F21) -> 3633000 | G22: =SUM(G6:G21) -> 24925000 | H22: =SUM(H6:H21) -> 1620842
A23: % Utilidad | B23: =B22/[1]Cotización!E69 -> 0.15828822 | F23: =D22+F22 -> 5333000
A26: RESUMEN RELACION DE PAGOS ANTES DEL EVENTO
A27: CONCEPTO | B27: TOTAL | C27: Pagado Corte 30 Sept | D27: Pagado día del evento | E27: Pte pagar DESPUES del evento
A28: RV PRODUCCION | B28: 35000000 | C28: 14000000 | D28: 3500000 | E28: =B28-C28-D28 -> 17500000
A29: OMAR CHAVEZ + Franklin | B29: 2600000 | C29: 0 | D29: 500000 | E29: =B29-C29-D29 -> 2100000
A30: ABA CARPAS | B30: 7700000 | C30: 4000000 | E30: =B30-C30-D30 -> 3700000
A31: INFLABLES | B31: 2000000 | D31: 2000000 | E31: =B31-C31-D31 -> 0
A32: TV+PS5 | B32: 1400000 | C32: 700000 | D32: 0 | E32: =B32-C32-D32 -> 700000
A33: FOTOGRAFIAS RICARDO | B33: 1100000 | C33: 0 | D33: 700000 | E33: =B33-C33-D33 -> 400000
A34: REFLECTORES | B34: 263060 | C34: 263060 | E34: =B34-C34-D34 -> 0
A35: CLAVIJAS REFLECTORES | B35: 63000 | C35: 63000 | E35: =B35-C35-D35 -> 0
A36: 40 MTS DE CABLE 2X16 | B36: 200000 | C36: 200000 | D36: 0 | E36: =B36-C36-D36 -> 0
A37: CAMISETA POLO BLANCA Y CAMISA AZUL | B37: 174000 | C37: 174000 | D37: 0 | E37: =B37-C37-D37 -> 0
A38: ALIMENTACIÓN | B38: 360000 | D38: 360000 | E38: =B38-C38-D38 -> 0
A39: RADIOS DE COMUNICACIÓN | B39: 160000 | C39: 160000 | E39: =B39-C39-D39 -> 0
A40: LUZ DE FERIA | B40: 484782 | C40: 484782 | E40: =B40-C40-D40 -> 0
A41: COMBUSTIBLE 07 SEPT | B41: 223916 | C41: 223916 | D41: 0
A42: IMPREVISTOS | B42: 1000000 | D42: 0
...

Sheet Cuentas Adicionales
A2: Cotizacion adicional | B2: 17085000
A3: Anticipo | B3: 0 | C3: ANTICIPO 1
A4: Mobiliario | B4: 6385000 | C4: 3750000
A5: Artisita fabio herrera | B5: 7500000 | C5: =B5*50% -> 3750000
A6: Bingo electronico | B6: 3200000 | C6: =B6*50% -> 1600000
A8: CONCEPTO | B8: TOTAL | C8: Pagado Corte 30 Sept | D8: Pagado día del evento | E8: Pte pagar DESPUES del evento
A9: DECORFIESTA | B9: 5360000 | C9: 3500000 | E9: =B9-C9-D9 -> 1860000
A10: JAVIER SILLAS | B10: 575000 | D10: 575000 | E10: =B10-C10-D10 -> 0
A11: BINGO ELECTRONICO | B11: 1700000 | C11: 750000 | D11: 950000 | E11: =B11-C11-D11 -> 0
A12: ARTISTA FABIO HERRERA | B12: 5000000 | C12: 0 | D12: 5000000 | E12: =B12-C12-D12 -> 0
A13: TOTAL | B13: =SUM(B9:B12) -> 12635000 | C13: =SUM(C9:C12) -> 4250000 | D13: =SUM(D9:D12) -> 6525000 | E13: =SUM(E9:E12) -> 1860000

Sheet Cuentas Bebidas
A2: RESUMEN RELACION DE PAGOS ANTES DEL EVENTO
A3: CONCEPTO | B3: TOTAL | C3: Pagado Corte 30 Sept | D3: Pagado día del evento | E3: Pagado | F3: Pte pagar DESPUES del evento
A4: COMPRA RADIOS | B4: 150000 | C4: 150000 | F4: =B4-C4-D4 -> 0
A5: PRESTAMO FRANCISCO | B5: 550000 | C5: 550000 | F5: =B5-C5-D5 -> 0
A6: POSTOBON | B6: 21208985 | C6: 9985000 | F6: =B6-C6-D6-E6 -> 11223985
A7: COCA COLA | B7: 3576600 | E7: 3576600 | F7: =B7-C7-D7-E7 -> 0
A8: EL REY DE LAS AGUAS | B8: 2529999 | C8: 3300000 | D8: Devolución $771000
A9: CHALECOS | B9: 975000 | C9: 450000 | D9: 525000 | F9: =B9-C9-D9-E9 -> 0
A10: GORRAS | B10: 235000 | C10: 50000 | D10: 185000 | F10: =B10-C10-D10-E10 -> 0
A11: CAMISETAS F3R | B11: 175000 | C11: 175000 | F11: =B11-C11-D11-E11 -> 0
A12: IMPREVISTOS | B12: 0 | D12: 0 | F12: =B12-C12-D12-E12 -> 0
A13: HIELO + TRANSPORTE | B13: 1400000 | D13: 1400000 | F13: =B13-C13-D13-E13 -> 0
A14: ALMUERZOS PERSONAL BEBIDAS | B14: 700000 | D14: 700000 | F14: =B14-C14-D14-E14 -> 0
A15: DATAFONOS BOLD | B15: 174000 | C15: 174000 | F15: =B15-C15-D15-E15 -> 0
A16: COMBUSTIBLE FR 30 SEPT | B16: 319338 | C16: 219338 | D16: 100000 | F16: =B16-C16-D16-E16 -> 0
A17: HIDRALITE ARA | B17: 96000 | C17: 96000 | F17: =B17-C17-D17-E17 -> 0
A18: CAJAS REGISTRADORAS | B18: 540264 | C18: 540264 | F18: =B18-C18-D18-E18 -> 0
A19: MENUDO DE CAJAS BEBIDAS | B19: =Bebidas!C42 -> 5000000 | C19: 5000000 | F19: =B19-C19-D19-E19 -> 0
A20: TOTAL | B20: =SUM(B4:B19) -> 37630186 | C20: =SUM(C4:C19) -> 20689602 | D20: =SUM(D4:D19) -> 2910000 | F20: =SUM(F4:F19) -> 11223985

Sheet Resumen Cuentas
B1: =B4 -> CONCEPTO | C1: =C4 -> TOTAL | D1: =D4 -> Pagado Corte 30 Sept | E1: =E4 -> Pagado día del evento | F1: =F4 -> Pte pagar DESPUES del evento | G1: GASTOS VS PAGOS | H1: VALIDADOR
B2: GASTOS TOTALES | C2: =C20+C25+C44 -> 95358944 | D2: =D20+D25+D44 -> 40958360 | E2: =E20+E25+E44 -> 14970000 | F2: =F20+F25+F44 -> 24400000 | G2: =C2-D2-E2-F2 -> 15030584 | H2: OK
B4: {='Cuentas Produccion'!A27:E43} -> CONCEPTO | C4: TOTAL | D4: Pagado Corte 30 Sept | E4: Pagado día del evento | F4: Pte pagar DESPUES del evento
B5: RV PRODUCCION | C5: 35000000 | D5: 14000000 | E5: 3500000 | F5: 17500000
B6: OMAR CHAVEZ + Franklin | C6: 2600000 | D6: 0 | E6: 500000 | F6: 2100000
B7: ABA CARPAS | C7: 7700000 | D7: 4000000 | E7: 0 | F7: 3700000
B8: INFLABLES | C8: 2000000 | D8: 0 | E8: 2000000 | F8: 0
B9: TV+PS5 | C9: 1400000 | D9: 700000 | E9: 0 | F9: 700000
B10: FOTOGRAFIAS RICARDO | C10: 1100000 | D10: 0 | E10: 700000 | F10: 400000
B11: REFLECTORES | C11: 263060 | D11: 263060 | E11: 0 | F11: 0
B12: CLAVIJAS REFLECTORES | C12: 63000 | D12: 63000 | E12: 0 | F12: 0
B13: 40 MTS DE CABLE 2X16 | C13: 200000 | D13: 200000 | E13: 0 | F13: 0
B14: CAMISETA POLO BLANCA Y CAMISA AZUL | C14: 174000 | D14: 174000 | E14: 0 | F14: 0
B15: ALIMENTACIÓN | C15: 360000 | D15: 0 | E15: 360000 | F15: 0
B16: RADIOS DE COMUNICACIÓN | C16: 160000 | D16: 160000 | E16: 0 | F16: 0
... B20: TOTAL PRODUCCIÓN | C20: 52728758 | D20: 20268758 | E20: 7060000 | F20: 24400000
B21: {='Cuentas Adicionales'!A8:E13} -> CONCEPTO | C21: TOTAL | D21: Pagado Corte 30 Sept | E21: Pagado día del evento | F21: Pte pagar DESPUES del evento
B22: DECORFIESTA | C22: 5360000 | D22: 3500000 | E22: 0 | F22: 1860000
B23: JAVIER SILLAS | C23: 575000 | D23: 0 | E23: 575000 | F23: 0
B24: BINGO ELECTRONICO | C24: 1700000 | D24: 750000 | E24: 950000 | F24: 0
B25: ARTISTA FABIO HERRERA | C25: 5000000 | D25: 0 | E25: 5000000 | F25: 0
B26: TOTAL | C26: 12635000 | D26: 4250000 | E26: 6525000 | F26: 1860000
B27: {='Cuentas Bebidas'!A3:F20} -> CONCEPTO | C27: TOTAL | D27: Pagado Corte 30 Sept | E27: Pagado día del evento | F27: Pagado | G27: Pte pagar DESPUES del evento
B28: COMPRA RADIOS | C28: 150000 | D28: 150000 | E28: 0 | F28: 0 | G28: 0
B29: PRESTAMO FRANCISCO | C29: 550000 | D29: 550000 | E29: 0 | F29: 0 | G29: 0
B30: POSTOBON | C30: 21208985 | D30: 9985000 | E30: 0 | F30: 0 | G30: 11223985
B31: COCA COLA | C31: 3576600 | D31: 0 | E31: 0 | F31: 3576600 | G31: 0
B32: EL REY DE LAS AGUAS | C32: 2529999 | D32: 3300000 | E32: Devolución $771000 | F32: 0 | G32: 0
B33: CHALECOS | C33: 975000 | D33: 450000 | E33: 525000 | F33: 0 | G33: 0
B34: GORRAS | C34: 235000 | D34: 50000 | E34: 185000 | F34: 0 | G34: 0
B35: CAMISETAS F3R | C35: 175000 | D35: 175000 | E35: 0 | F35: 0 | G35: 0
B36: IMPREVISTOS | C36: 0 | D36: 0 | E36: 0 | F36: 0 | G36: 0
B37: HIELO + TRANSPORTE | C37: 1400000 | D37: 0 | E37: 1400000 | F37: 0 | G37: 0
B38: ALMUERZOS PERSONAL BEBIDAS | C38: 700000 | D38: 0 | E38: 700000 | F38: 0 | G38: 0
B39: DATAFONOS BOLD | C39: 174000 | D39: 174000 | E39: 0 | F39: 0 | G39: 0
B40: COMBUSTIBLE FR 30 SEPT | C40: 319338 | D40: 219338 | E40: 100000 | F40: 0 | G40: 0
B41: HIDRALITE ARA | C41: 96000 | D41: 96000 | E41: 0 | F41: 0 | G41: 0
B42: CAJAS REGISTRADORAS | C42: 540264 | D42: 540264 | E42: 0 | F42: 0 | G42: 0
B43: MENUDO DE CAJAS BEBIDAS | C43: 5000000 | D43: 5000000 | E43: 0 | F43: 0 | G43: 0
B44: TOTAL | C44: 37630186 | D44: 20689602 | E44: 2910000 | F44: 0 | G44: 11223985

Sheet Resumen pagos 
A2: RESUMEN RELACION DE PAGOS ANTES DEL EVENTO
A3: CONCEPTO | B3: VALOR | C3: TITULAR | D3: CUENTA | E3: TIPO | F3: BANCO
A4: PLAY STATION | B4: ='Cuentas Produccion'!F10 -> 700000 | C4: ORLANDO MENDOZA | D4: 17553786851 | E4: AHORROS | F4: BANCOLOMBIA
A5: DECORFIESTAS | B5: 3500000 | C5: NERVA ESTHER DIAZ | D5: O989951961 | E5: AHORROS | F5: BANCOLOMBIA
A6: BINGO ELECTRONICO | B6: 750000 | C6: CONSIGNACION
A7: RV | B7: 3500000 | C7: EFECTIVO | D7: EFECTIVO | E7: EFECTIVO | F7: EFECTIVO
A8: COMPRA RADIOS | B8: 200000
A9: PRESTAMO FRANCISCO | B9: 550000
A10: INFLABLES | B10: ='Cuentas Produccion'!F9 -> 1048000
A11: POSTOBON | B11: 9985000
A12: COCA COLA | B12: =Bebidas!C44 -> 3387330.2
A13: EL REY DE LAS AGUAS | B13: 3300000
A14: CHALECOS | B14: ='Cuentas Produccion'!F12 -> 525000
A15: GORRAS | B15: 50000
A16: CAMISETAS F3R | B16: 175000
A17: IMPREVISTOS PRODUCCION | B17: ='Cuentas Produccion'!F17 -> 1000000
A18: HIELO + TRANSPORTE | B18: =Bebidas!C36 -> 1285000
A19: ALMUERZOS PERSONAL BEBIDAS | B19: =Bebidas!C40 -> 225000
A20: ALMUERZOS PERSONAL PRODUCCION | B20: ='Cuentas Produccion'!F14 -> 360000
A21: MENUDO DE CAJAS BEBIDAS | B21: =Bebidas!C42 -> 5000000
A22: TOTAL | B22: =SUM(B4:B21) -> 35540330
A26: FLUJO DE CAJA | B26: ='Cuentas Produccion'!B3+'Cuentas Produccion'!B4 -> 42000000
A27: PAGOS REALIZADOS | B27: =B4+B5+B6+B9+B21+B11+B8 -> 20685000
A28: ='Cuentas Produccion'!A6 -> RV | B28: ='Cuentas Produccion'!C6 -> 14000000 | D28: =B22-B30 -> 32225330
A29: ='Cuentas Produccion'!A8 -> Aba Carpas | B29: ='Cuentas Produccion'!C8 -> 4000000
A30: SALDO EN CAJA | B30: =B26-B28-B29-B27 -> 3315000

Sheet Hoja1
A1: DIDIER | B1: PATRICIA | C1: OROZCO | D1: DE AVILA | E1: 45591156
A2: KELLY | B2: JOHANA | C2: CAMACHO | D2: CONTRERAS | E2: 45706484
A3: MARTHA | B3: VERONICA | C3: ZAPATEIRO | D3: ESQUIVIA | E3: 45533328
A4: FABIAN | B4: CAMILO | C4: INFANTE | D4: RODRIGUEZ | E4: 1043295335
A5: SIXTA | B5: MILENA | C5: GARY | D5: HURTADO | E5: 45535632
